<?xml version='1.0' encoding='UTF-8'?>
<robot name='joint_example'>
  <link name='base_link'>
    <inertial>
      <mass value='0.12' />
      <inertia ixx='0.01' ixy='0' ixz='0' iyy='0.01' iyz='0' izz='0.01' />
    </inertial>
  </link>
  <joint name='j1' type='continuous'>
    <parent link='base_link'/>
    <child link='end_effector'/>
    <origin xyz='0 0 1' rpy='0 0 0'/>
  </joint>
  <link name='end_effector'>
    <inertial>
      <mass value='0.12' />
      <inertia ixx='0.01' ixy='0' ixz='0' iyy='0.01' iyz='0' izz='0.01' />
    </inertial>
  </link>
  <gazebo reference='j1'>
    <springReference>0.5</springReference>
    <springStiffness>0.25</springStiffness>
  </gazebo>
</robot>

